<?xml version="1.0"?>
<!-- created with Phobos 1.0.1 "Capricious Choutengan" -->
  <robot name="rhea">

    <link name="base_link">
      <inertial>
        <origin xyz="0 0 0" rpy="0 0 0"/>
        <mass value="4.0"/>
        <inertia ixx="0.01" ixy="0" ixz="0" iyy="0.01" iyz="0" izz="0.01"/>
      </inertial>
      <visual name="rheav2">
        <origin xyz="0 0 0" rpy="0 0 0"/>
        <geometry>
          <mesh filename="package://rhea_description/meshes/dae/rheav2.dae" scale="1.0 1.0 1.0"/>
        </geometry>
        <material name="Rubber_-_Soft.002"/>
      </visual>
      <collision name="Cube">
        <origin xyz="0 0 -0.01575" rpy="0 0 0"/>
        <geometry>
          <box size="0.216 0.14 0.231"/>
        </geometry>
      </collision>
    </link>

    <link name="imu">
      <inertial>
        <origin xyz="0 0 0" rpy="0 0 0"/>
        <mass value="0.001"/>
        <inertia ixx="0.001" ixy="0" ixz="0" iyy="0.001" iyz="0" izz="0.001"/>
      </inertial>
    </link>

    <link name="left_hip">
      <inertial>
        <origin xyz="0 0 0" rpy="0 0 0"/>
        <mass value="1.0"/>
        <inertia ixx="0.01" ixy="0" ixz="0" iyy="0.01" iyz="0" izz="0.01"/>
      </inertial>
      <visual name="rheav2.006">
        <origin xyz="0 0 0" rpy="1.5708 0 -1.5708"/>
        <geometry>
          <mesh filename="package://rhea_description/meshes/dae/rheav2.006.dae" scale="1.0 1.0 1.0"/>
        </geometry>
        <material name="Rubber_-_Soft.002"/>
      </visual>
      <collision name="Cube.004">
        <origin xyz="0.09575 0 0" rpy="1.5708 0 -1.5708"/>
        <geometry>
          <box size="0.05693 0.0756 0.30004"/>
        </geometry>
      </collision>
    </link>

    <link name="left_knee">
      <inertial>
        <origin xyz="0 0 0" rpy="0 0 0"/>
        <mass value="0.5"/>
        <inertia ixx="0.01" ixy="0" ixz="0" iyy="0.01" iyz="0" izz="0.01"/>
      </inertial>
      <visual name="rheav2.004">
        <origin xyz="0 0 0" rpy="1.5708 0 -1.5708"/>
        <geometry>
          <mesh filename="package://rhea_description/meshes/dae/rheav2.004.dae" scale="1.0 1.0 1.0"/>
        </geometry>
        <material name="Rubber_-_Soft.002"/>
      </visual>
      <collision name="Cube.003">
        <origin xyz="0.12575 0 0" rpy="1.5708 0 -1.5708"/>
        <geometry>
          <box size="0.05693 0.028 0.30004"/>
        </geometry>
      </collision>
    </link>

    <link name="left_wheel">
      <inertial>
        <origin xyz="0 0 0" rpy="0 0 0"/>
        <mass value="1.0"/>
        <inertia ixx="0.01" ixy="0" ixz="0" iyy="0.01" iyz="0" izz="0.01"/>
      </inertial>
      <visual name="rheav2.005">
        <origin xyz="0 0 0.0445" rpy="1.5708 0 -1.5708"/>
        <geometry>
          <mesh filename="package://rhea_description/meshes/dae/rheav2.005.dae" scale="1.0 1.0 1.0"/>
        </geometry>
        <material name="Rubber_-_Soft.002"/>
      </visual>
      <collision name="Cylinder.003">
        <origin xyz="0 0 0.0445" rpy="0 0 -1.0472"/>
        <geometry>
          <cylinder radius="0.11" length="0.048"/>
        </geometry>
      </collision>
    </link>

    <link name="right_hip">
      <inertial>
        <origin xyz="0 0 0" rpy="0 0 0"/>
        <mass value="1.0"/>
        <inertia ixx="0.01" ixy="0" ixz="0" iyy="0.01" iyz="0" izz="0.01"/>
      </inertial>
      <visual name="rheav2.003">
        <origin xyz="0 0 0" rpy="-1.5708 0 1.5708"/>
        <geometry>
          <mesh filename="package://rhea_description/meshes/dae/rheav2.003.dae" scale="1.0 1.0 1.0"/>
        </geometry>
        <material name="Rubber_-_Soft.002"/>
      </visual>
      <collision name="Cube.002">
        <origin xyz="0.09575 0 0" rpy="-1.5708 0 1.5708"/>
        <geometry>
          <box size="0.05693 0.0756 0.30004"/>
        </geometry>
      </collision>
    </link>

    <link name="right_knee">
      <inertial>
        <origin xyz="0 0 0" rpy="0 0 0"/>
        <mass value="0.5"/>
        <inertia ixx="0.01" ixy="0" ixz="0" iyy="0.01" iyz="0" izz="0.01"/>
      </inertial>
      <visual name="rheav2.001">
        <origin xyz="0 0 0" rpy="-1.5708 0 1.5708"/>
        <geometry>
          <mesh filename="package://rhea_description/meshes/dae/rheav2.001.dae" scale="1.0 1.0 1.0"/>
        </geometry>
        <material name="Rubber_-_Soft.002"/>
      </visual>
      <collision name="Cube.001">
        <origin xyz="0.12575 0 0" rpy="-1.5708 0 1.5708"/>
        <geometry>
          <box size="0.05693 0.028 0.30004"/>
        </geometry>
      </collision>
    </link>

    <link name="right_wheel">
      <inertial>
        <origin xyz="0 0 0" rpy="0 0 0"/>
        <mass value="1.0"/>
        <inertia ixx="0.01" ixy="0" ixz="0" iyy="0.01" iyz="0" izz="0.01"/>
      </inertial>
      <visual name="rheav2.002">
        <origin xyz="0 0 0.0445" rpy="-1.5708 0 1.5708"/>
        <geometry>
          <mesh filename="package://rhea_description/meshes/dae/rheav2.002.dae" scale="1.0 1.0 1.0"/>
        </geometry>
        <material name="Rubber_-_Soft.002"/>
      </visual>
      <collision name="Cylinder.001">
        <origin xyz="0 0 0.0445" rpy="0 0 1.0472"/>
        <geometry>
          <cylinder radius="0.11" length="0.048"/>
        </geometry>
      </collision>
    </link>

    <joint name="imu" type="fixed">
      <origin xyz="0 0 0" rpy="1.5708 0 -1.5708"/>
      <parent link="base_link"/>
      <child link="imu"/>
    </joint>

    <joint name="left_hip" type="revolute">
      <origin xyz="0 0.1255 0" rpy="-1.5708 1.5708 0"/>
      <parent link="base_link"/>
      <child link="left_hip"/>
      <axis xyz="0 0 1.0"/>
      <limit lower="-0.68068" upper="2.46091" effort="35.0" velocity="26.0"/>
    </joint>

    <joint name="left_knee" type="revolute">
      <origin xyz="0.25 0 0" rpy="0 0 0"/>
      <parent link="left_hip"/>
      <child link="left_knee"/>
      <axis xyz="0 0 1.0"/>
      <limit lower="-2.75762" upper="-0.66323" effort="35.0" velocity="26.0"/>
    </joint>

    <joint name="left_wheel" type="continuous">
      <origin xyz="0.25 0 0" rpy="0 0 0"/>
      <parent link="left_knee"/>
      <child link="left_wheel"/>
      <axis xyz="0 0 1.0"/>
      <limit effort="2.0" velocity="250.0"/>
    </joint>

    <joint name="right_hip" type="revolute">
      <origin xyz="0 -0.1255 0" rpy="1.5708 1.5708 0"/>
      <parent link="base_link"/>
      <child link="right_hip"/>
      <axis xyz="0 0 1.0"/>
      <limit lower="-2.46091" upper="0.68068" effort="35.0" velocity="26.0"/>
    </joint>

    <joint name="right_knee" type="revolute">
      <origin xyz="0.25 0 0" rpy="0 0 0"/>
      <parent link="right_hip"/>
      <child link="right_knee"/>
      <axis xyz="0 0 1.0"/>
      <limit lower="0.66323" upper="2.75762" effort="35.0" velocity="26.0"/>
    </joint>

    <joint name="right_wheel" type="continuous">
      <origin xyz="0.25 0 0" rpy="0 0 0"/>
      <parent link="right_knee"/>
      <child link="right_wheel"/>
      <axis xyz="0 0 1.0"/>
      <limit effort="2.0" velocity="250.0"/>
    </joint>

    <material name="Rubber_-_Soft.002">
      <color rgba="0.15294 0.15294 0.15294 1.0"/>
    </material>

  </robot>
